2018-05-30 15:28:21 ERROR (MainThread) [aiohttp.server] Error handling request
Traceback (most recent call last):
  File "/usr/local/lib/python3.6/site-packages/aiohttp/web_protocol.py", line 231, in data_received
    messages, upgraded, tail = self._request_parser.feed_data(data)
  File "aiohttp/_http_parser.pyx", line 297, in aiohttp._http_parser.HttpParser.feed_data
aiohttp.http_exceptions.BadStatusLine: invalid HTTP method
2018-05-30 15:28:21 ERROR (MainThread) [aiohttp.server] Error handling request
Traceback (most recent call last):
  File "/usr/local/lib/python3.6/site-packages/aiohttp/web_protocol.py", line 231, in data_received
    messages, upgraded, tail = self._request_parser.feed_data(data)
  File "aiohttp/_http_parser.pyx", line 297, in aiohttp._http_parser.HttpParser.feed_data
aiohttp.http_exceptions.BadStatusLine: invalid HTTP method
2018-05-30 15:28:21 ERROR (MainThread) [aiohttp.server] Error handling request
Traceback (most recent call last):
  File "/usr/local/lib/python3.6/site-packages/aiohttp/web_protocol.py", line 231, in data_received
    messages, upgraded, tail = self._request_parser.feed_data(data)
  File "aiohttp/_http_parser.pyx", line 297, in aiohttp._http_parser.HttpParser.feed_data
aiohttp.http_exceptions.BadStatusLine: invalid HTTP method
2018-05-30 15:28:21 ERROR (MainThread) [aiohttp.server] Error handling request
Traceback (most recent call last):
  File "/usr/local/lib/python3.6/site-packages/aiohttp/web_protocol.py", line 231, in data_received
    messages, upgraded, tail = self._request_parser.feed_data(data)
  File "aiohttp/_http_parser.pyx", line 297, in aiohttp._http_parser.HttpParser.feed_data
aiohttp.http_exceptions.BadStatusLine: invalid HTTP method
2018-05-30 20:46:06 WARNING (Thread-3) [pychromecast.socket_client] Heartbeat timeout, resetting connection
2018-05-30 20:46:09 ERROR (Thread-3) [pychromecast.socket_client] Failed to connect, retrying in 5.0s
2018-05-30 20:55:02 WARNING (MainThread) [homeassistant.components.media_player] Platform cast not ready yet. Retrying in 30 seconds.
2018-05-30 21:47:50 WARNING (Thread-3) [pychromecast.socket_client] Heartbeat timeout, resetting connection
2018-05-30 21:47:52 WARNING (Thread-2) [pychromecast.socket_client] Heartbeat timeout, resetting connection
2018-05-30 21:47:54 WARNING (MainThread) [homeassistant.components.switch.wemo] Lost connection to WeMo Light Switch
2018-05-30 21:47:59 WARNING (SyncWorker_3) [pywemo.ouimeaux_device.api.service] Error communicating with WeMo Light Switch, retry 0
2018-05-30 21:48:09 ERROR (SyncWorker_3) [pywemo.ouimeaux_device] Unable to re-probe wemo at 10.88.111.2
2018-05-30 21:48:20 ERROR (Thread-3) [pychromecast.socket_client] Failed to connect, retrying in 5.0s
2018-05-30 21:48:22 ERROR (Thread-2) [pychromecast.socket_client] Failed to connect, retrying in 5.0s
2018-05-30 21:58:28 ERROR (MainThread) [coap] Exception CancelledError() can not be represented as errno, setting -1.
2018-05-30 22:13:20 WARNING (Thread-3) [pychromecast.socket_client] Heartbeat timeout, resetting connection
2018-05-30 22:17:23 WARNING (Thread-3) [pychromecast.socket_client] Heartbeat timeout, resetting connection
2018-05-30 22:18:09 WARNING (Thread-3) [pychromecast.socket_client] Heartbeat timeout, resetting connection
2018-05-30 22:19:24 WARNING (Thread-3) [pychromecast.socket_client] Heartbeat timeout, resetting connection
2018-05-30 22:21:38 WARNING (Thread-3) [pychromecast.socket_client] Heartbeat timeout, resetting connection
2018-05-30 22:53:07 WARNING (Thread-3) [pychromecast.socket_client] Heartbeat timeout, resetting connection
2018-05-30 23:41:15 WARNING (Thread-3) [pychromecast.socket_client] Heartbeat timeout, resetting connection
2018-05-30 23:51:49 WARNING (Thread-3) [pychromecast.socket_client] Heartbeat timeout, resetting connection
2018-05-31 00:12:14 WARNING (MainThread) [homeassistant.components.http.ban] Login attempt or request with invalid authentication from 209.15.25.82
